Workbook
Name Txt_SinDatos: _Textos!$B$2
Name Txt_SinVentas: _Textos!$B$3
Name Txt_SinProductos: _Textos!$B$4
Name Txt_ProductoNoEncontrado: _Textos!$B$5
Name Txt_ObjetivoInvalido: _Textos!$B$6
Name Txt_ObjetivoAlcanzado: _Textos!$B$7
Name Txt_FaltaHistorial: _Textos!$B$8
Name Txt_NombreDuplicado: _Textos!$B$9
Name Txt_SinAlertas: _Textos!$B$10
Name Txt_UltimoDia: _Textos!$B$11
Name Cfg_NombreNegocio: '⚙️ Configuración'!$C$11
Name Cfg_TipoNegocio: '⚙️ Configuración'!$C$12
Name Cfg_Moneda: '⚙️ Configuración'!$C$13
Name Cfg_ObjetivoMensualDefault: '⚙️ Configuración'!$C$24
Name Cfg_PeriodoInicio: _Config!$B$6
Name Cfg_PeriodoFin: _Config!$B$7
Name Cfg_MargenAlertaUmbral: _Config!$B$8
Name Cfg_PeriodoInicio_Ant: _Config!$B$10
Name Cfg_PeriodoFin_Ant: _Config!$B$11
Name Lst_Categorias: _Listas!$A$2:$A$8
Name Lst_Canales: _Listas!$B$2:$B$6
Name Lst_CategoriasGasto: _Listas!$C$2:$C$7
Name Lst_TiposGasto: _Listas!$D$2:$D$4
Name Lst_Monedas: _Listas!$E$2:$E$6
Name Lst_PeriodosRapidos: _Listas!$F$2:$F$5
Name GastosCalc_PeriodoActual: _GastosCalc!$B$2
Name GastosCalc_PeriodoAnterior: _GastosCalc!$B$3
Name KPI_VentasPeriodo: _DashboardData!$B$2
Name KPI_VentasPeriodo_Ant: _DashboardData!$C$2
Name KPI_CostosVentaPeriodo: _DashboardData!$B$3
Name KPI_CostosVentaPeriodo_Ant: _DashboardData!$C$3
Name KPI_GananciaProductos: _DashboardData!$B$4
Name KPI_GananciaProductos_Ant: _DashboardData!$C$4
Name KPI_GastosPeriodo: _DashboardData!$B$5
Name KPI_GastosPeriodo_Ant: _DashboardData!$C$5
Name KPI_GananciaReal: _DashboardData!$B$6
Name KPI_GananciaReal_Ant: _DashboardData!$C$6
Name KPI_MargenReal: _DashboardData!$B$7
Name KPI_MargenReal_Ant: _DashboardData!$C$7
Name KPI_CantidadVentas: _DashboardData!$B$8
Name KPI_CantidadVentas_Ant: _DashboardData!$C$8
Name KPI_TicketPromedio: _DashboardData!$B$9
Name KPI_TicketPromedio_Ant: _DashboardData!$C$9
Name KPI_VentasPeriodo_Delta: _DashboardData!$B$13
Name KPI_GananciaReal_Delta: _DashboardData!$B$14
Name KPI_MargenReal_Delta: _DashboardData!$B$15
Name KPI_GastosPeriodo_Delta: _DashboardData!$B$16
Name KPI_TicketPromedio_Delta: _DashboardData!$B$17
Name Dash_DiasHistorial: _DashboardData!$B$20
Name Dash_Granularidad: _DashboardData!$B$21
Name Dash_TrendRange: _DashboardData!$A$22:$C$28
Name Dash_ProductoRange: _DashboardData!$A$32:$B$41
Name Obj_GananciaObjetivo: _Objetivos_Calc!$B$2
Name Obj_GananciaActual: _Objetivos_Calc!$B$3
Name Obj_Restante: _Objetivos_Calc!$B$4
Name Obj_ProgresoPct: _Objetivos_Calc!$B$5
Name Obj_DiasRestantes: _Objetivos_Calc!$B$6
Name Obj_GananciaDiariaNecesaria: _Objetivos_Calc!$B$7
Name Obj_FacturacionNecesaria: _Objetivos_Calc!$B$8
Name Obj_VentasNecesarias: _Objetivos_Calc!$B$9

Sheet 🧭 Menú
B3: PROFITLY — CENTRO DE CONTROL DE RENTABILIDAD
B5: Sabé exactamente cuánto ganás, qué te hace ganar dinero y qué decisiones pueden aumentar tu rentabilidad.
C9: 🎬 Ver una demo Mirá un ejemplo con datos ficticios y entendé cómo funciona Profitly. Entrar → | I9: 🚀 Empezar con mi negocio Cargá tus productos y ventas reales y llevá el control de tu rentabilidad. Entrar →
B17: ¿Primera vez? Te recomendamos empezar por la Demo.

Sheet 🏠 Inicio
B1: 🏠 Inicio | D1: ⚙️ Configuración | F1: 📦 Productos | H1: 🛒 Ventas | J1: 💸 Gastos | L1: 🎯 Objetivos | N1: 🔬 Simulador | Q1: ="Mi Negocio · "&Cfg_NombreNegocio
B3: 🏠 INICIO
B4: Tu negocio, en números.
B6: =IF(COUNTA(tbl_Productos[Producto])=0,"🚀 Te falta 1 paso para ver tu panorama completo: Configurá tu negocio y agregá productos → Ir a ⚙️ Configuración",IF(COUNTA(tbl_Ventas[Fecha])=0,"🚀 Te falta 1 paso: Registrá tu primera venta → Ir a 🛒 Ventas",IF(COUNTA(tbl_Gastos[Fecha])=0,"🚀 Te falta 1 paso: Registrá tus gastos → Ir a 💸 Gastos",IF(OR(Cfg_ObjetivoMensualDefault=0,COUNTA(tbl_Objetivos[Objetivo de ganancia])<=1),"🚀 Te falta 1 paso: Definí tu objetivo mensual → Ir a 🎯 Objetivos",""))))
F7: Viendo: | G7: Este mes
B9: VENTAS | F9: GANANCIA REAL | J9: MARGEN | N9: GASTOS
B10: =KPI_VentasPeriodo | F10: =KPI_GananciaReal | J10: =KPI_MargenReal | N10: =KPI_GastosPeriodo
B11: =IF(KPI_VentasPeriodo_Delta="","",IF(KPI_VentasPeriodo_Delta>0,"▲ ","▼ ")&TEXT(ABS(KPI_VentasPeriodo_Delta),"0%")&" vs. período anterior") | F11: =IF(KPI_GananciaReal_Delta="","",IF(KPI_GananciaReal_Delta>0,"▲ ","▼ ")&TEXT(ABS(KPI_GananciaReal_Delta),"0%")&" vs. período anterior") | J11: =IF(KPI_MargenReal_Delta="","",IF(KPI_MargenReal_Delta>0,"▲ ","▼ ")&TEXT(ABS(KPI_MargenReal_Delta),"0%")&" vs. período anterior") | N11: =IF(KPI_GastosPeriodo_Delta="","",IF(KPI_GastosPeriodo_Delta<0,"▲ ","▼ ")&TEXT(ABS(KPI_GastosPeriodo_Delta),"0%")&" vs. período anterior")
B13: TICKET PROMEDIO | F13: OBJETIVO MENSUAL | J13: PROGRESO
B14: =KPI_TicketPromedio | F14: =Obj_GananciaObjetivo | J14: =IFERROR(Obj_ProgresoPct,0)
B17: 💡 Lo que Profitly encontró en tus números
B18: =Ins_Texto1
B19: =Ins_Texto2
B20: =Ins_Texto3
B21: =Ins_Texto4

Sheet ⚙️ Configuración
B1: 🏠 Inicio | D1: ⚙️ Configuración | F1: 📦 Productos | H1: 🛒 Ventas | J1: 💸 Gastos | L1: 🎯 Objetivos | N1: 🔬 Simulador | Q1: ="Mi Negocio · "&Cfg_NombreNegocio
B3: ⚙️ CONFIGURACIÓN
B4: Configurá tu negocio una vez — Profitly usa esto en todas las pantallas.
B6: 1. Configurá tu negocio | E6: 2. Agregá tus productos →📦 | H6: 3. Registrá tus ventas →🛒 | K6: 4. Registrá tus gastos →💸 | N6: 5. Mirá tu rentabilidad →🏠
B7: =IF(AND(Cfg_NombreNegocio<>"",Cfg_Moneda<>""),"✅","⬜") | E7: =IF(COUNTA(tbl_Productos[Producto])>0,"✅","⬜") | H7: =IF(COUNTA(tbl_Ventas[Fecha])>0,"✅","⬜") | K7: =IF(COUNTA(tbl_Gastos[Fecha])>0,"✅","⬜") | N7: =IF(AND(COUNTA(tbl_Productos[Producto])>0,COUNTA(tbl_Ventas[Fecha])>0),"✅","⬜")
B10: Tu negocio
B11: Nombre del negocio | C11: Mi Negocio
B12: Tipo de negocio
B13: Moneda | C13: $
B15: Categorías de productos
B16: (Se cargan en 📦 Productos como lista desplegable — editá la lista base en la hoja _Listas.)
B18: Canales de venta
B19: (Se cargan en 🛒 Ventas como lista desplegable — editá la lista base en la hoja _Listas.)
B21: 💡 Cargá tus gastos fijos (alquiler, herramientas, suscripciones) en 💸 Gastos para que tu Ganancia real sea precisa.
B23: Objetivo mensual
B24: ¿Cuánto querés ganar por mes? | C24: 0
B26: No hay botón "Guardar" — todo se guarda automáticamente a medida que escribís, como en cualquier planilla.

Sheet 📦 Productos
B1: 🏠 Inicio | D1: ⚙️ Configuración | F1: 📦 Productos | H1: 🛒 Ventas | J1: 💸 Gastos | L1: 🎯 Objetivos | N1: 🔬 Simulador | Q1: ="Mi Negocio · "&Cfg_NombreNegocio
B3: 📦 PRODUCTOS
B4: Tu catálogo de productos y cuánto te deja ganar cada uno.
B6: Tus productos, en números
B7: 🏆 Más rentable | F7: 🔥 Más vendido | J7: 💰 Más dinero genera | N7: ⚠️ Margen bajo
B8: =IF(COUNTIFS(tbl_Productos[Unidades vendidas],">0")=0,Txt_SinVentas,INDEX(tbl_Productos[Producto],MATCH(_xlfn.MAXIFS(tbl_Productos[Margen],tbl_Productos[Unidades vendidas],">0"),tbl_Productos[Margen],0))) | F8: =IF(COUNTA(tbl_Productos[Producto])=0,Txt_SinProductos,IF(MAX(tbl_Productos[Unidades vendidas])=0,Txt_SinVentas,INDEX(tbl_Productos[Producto],MATCH(MAX(tbl_Productos[Unidades vendidas]),tbl_Productos[Unidades vendidas],0)))) | J8: =IF(COUNTA(tbl_Productos[Producto])=0,Txt_SinProductos,IF(MAX(tbl_Productos[Ganancia total])<=0,Txt_SinVentas,INDEX(tbl_Productos[Producto],MATCH(MAX(tbl_Productos[Ganancia total]),tbl_Productos[Ganancia total],0)))) | N8: =IFERROR(INDEX(tbl_Productos[Producto],MATCH(1,tbl_Productos[Alerta margen bajo],0)),Txt_SinAlertas)
B9: =IFERROR(_xlfn.MAXIFS(tbl_Productos[Margen],tbl_Productos[Unidades vendidas],">0"),"") | F9: =IF(OR(COUNTA(tbl_Productos[Producto])=0,MAX(tbl_Productos[Unidades vendidas])=0),"",MAX(tbl_Productos[Unidades vendidas])&" unidades") | J9: =IF(OR(COUNTA(tbl_Productos[Producto])=0,MAX(tbl_Productos[Ganancia total])<=0),"",MAX(tbl_Productos[Ganancia total])) | N9: =IFERROR(INDEX(tbl_Productos[Margen],MATCH(1,tbl_Productos[Alerta margen bajo],0)),"")
B11: ⬜ Vos cargás esto · 🔸 Profitly lo completa (lo podés cambiar) · 🔒 Profitly lo calculó
B12: Producto | C12: Categoría | D12: Precio de venta | E12: Costo del producto | F12: Comisión % | G12: Packaging | H12: Envío / costo asociado | I12: Publicidad atribuida | J12: Otros costos | K12: Costo real de venta | L12: Ganancia por unidad | M12: Margen | N12: Unidades vendidas | O12: Ganancia total | P12: Alerta margen bajo
K13: =E13+(D13*F13)+G13+H13+I13+J13 | L13: =D13-K13 | M13: =IF(D13=0,Txt_SinDatos,L13/D13) | N13: =SUMIFS(tbl_Ventas[Cantidad],tbl_Ventas[Producto],B13) | O13: =SUMIFS(tbl_Ventas[Ganancia],tbl_Ventas[Producto],B13) | P13: =IF(AND(ISNUMBER(M13),M13<Cfg_MargenAlertaUmbral,N13>0),1,0)
B15: =IF(COUNTA(tbl_Productos[Producto])=0,"Todavía no tenés productos cargados. Agregá el primero para empezar 👇","")

Sheet 🛒 Ventas
B1: 🏠 Inicio | D1: ⚙️ Configuración | F1: 📦 Productos | H1: 🛒 Ventas | J1: 💸 Gastos | L1: 🎯 Objetivos | N1: 🔬 Simulador | Q1: ="Mi Negocio · "&Cfg_NombreNegocio
B3: 🛒 VENTAS
B4: Registrá tus ventas — Profitly calcula el resto.
B6: ="Ventas este mes: "&COUNTIFS(tbl_Ventas[Fecha],">="&Cfg_PeriodoInicio,tbl_Ventas[Fecha],"<="&Cfg_PeriodoFin)&" registros" | G6: =IF(COUNTA(tbl_Ventas[Fecha])=0,"Última venta: —","Última venta: "&TEXT(MAX(tbl_Ventas[Fecha]),"DD/MM/YYYY"))
B7: =IF(COUNTA(tbl_Productos[Producto])=0,"Necesitás cargar al menos un producto antes de registrar ventas. → Ir a 📦 Productos","")
B8: ⬜ Vos cargás esto · 🔸 Profitly lo completa (lo podés cambiar) · 🔒 Profitly lo calculó
B9: Fecha | C9: Producto | D9: Cantidad | E9: Precio de venta | F9: Canal | G9: Comisión % | H9: Descuento | I9: Otros costos | J9: Venta total | K9: Costo total de la venta | L9: Ganancia
E10: =IFERROR(INDEX(tbl_Productos[Precio de venta],MATCH(C10,tbl_Productos[Producto],0)),"") | G10: =IFERROR(INDEX(tbl_Productos[Comisión %],MATCH(C10,tbl_Productos[Producto],0)),"") | J10: =IF(C10="","",(D10*E10)-H10) | K10: =IF(C10="","",IFERROR(INDEX(tbl_Productos[Costo real de venta],MATCH(C10,tbl_Productos[Producto],0))*D10,Txt_ProductoNoEncontrado)) | L10: =IF(C10="","",IFERROR(J10-K10-I10,Txt_ProductoNoEncontrado))
B12: =IF(AND(COUNTA(tbl_Productos[Producto])>0,COUNTA(tbl_Ventas[Fecha])=0),"Registrá tu primera venta para empezar a ver tu rentabilidad 👇","")

Sheet 💸 Gastos
B1: 🏠 Inicio | D1: ⚙️ Configuración | F1: 📦 Productos | H1: 🛒 Ventas | J1: 💸 Gastos | L1: 🎯 Objetivos | N1: 🔬 Simulador | Q1: ="Mi Negocio · "&Cfg_NombreNegocio
B3: 💸 GASTOS
B4: Los gastos generales de tu negocio, separados de los costos de cada venta.
B6: ⓘ Acá cargás los gastos generales de tu negocio (alquiler, software, herramientas). Los costos de cada venta — comisión, envío, packaging, publicidad — se cargan en 📦 Productos.
B7: ="Gastos del negocio este mes: "&TEXT(SUMIFS(tbl_Gastos[Importe],tbl_Gastos[Fecha],">="&Cfg_PeriodoInicio,tbl_Gastos[Fecha],"<="&Cfg_PeriodoFin),Cfg_Moneda&"#,##0")
B9: Fecha | C9: Categoría | D9: Descripción | E9: Importe | F9: Tipo de gasto
B12: =IF(COUNTA(tbl_Gastos[Fecha])=0,"Todavía no cargaste gastos del negocio. Si por ahora no tenés, tu Ganancia real usa $0 — podés agregar gastos en cualquier momento.","")

Sheet 🎯 Objetivos
B1: 🏠 Inicio | D1: ⚙️ Configuración | F1: 📦 Productos | H1: 🛒 Ventas | J1: 💸 Gastos | L1: 🎯 Objetivos | N1: 🔬 Simulador | Q1: ="Mi Negocio · "&Cfg_NombreNegocio
B3: 🎯 OBJETIVOS
B4: Cuánto querés ganar, y qué te falta para lograrlo.
B6: Periodo (Mes-Año) | C6: Objetivo de ganancia | F6: Progreso hacia tu objetivo
C7: =Cfg_ObjetivoMensualDefault | F7: =IF(Obj_GananciaObjetivo<=0,Txt_ObjetivoInvalido,TEXT(Obj_ProgresoPct,"0%")&" · "&TEXT(Obj_GananciaActual,Cfg_Moneda&"#,##0")&" de "&TEXT(Obj_GananciaObjetivo,Cfg_Moneda&"#,##0"))
B9: =IF(AND(Cfg_ObjetivoMensualDefault=0,COUNTA(tbl_Objetivos[Objetivo de ganancia])<=1),"Todavía no definiste un objetivo. ¿Cuánto querés ganar este mes?","") | F9: Ganancia objetivo | H9: =Obj_GananciaObjetivo
F10: Ganancia actual | H10: =Obj_GananciaActual
F11: Restante | H11: =Obj_Restante
F12: Ganancia diaria necesaria | H12: =Obj_GananciaDiariaNecesaria
F13: Facturación necesaria | H13: =Obj_FacturacionNecesaria
F14: Ventas necesarias | H14: =Obj_VentasNecesarias
F16: =Obj_Factibilidad

Sheet 🔬 Simulador
B1: 🏠 Inicio | D1: ⚙️ Configuración | F1: 📦 Productos | H1: 🛒 Ventas | J1: 💸 Gastos | L1: 🎯 Objetivos | N1: 🔬 Simulador | Q1: ="Mi Negocio · "&Cfg_NombreNegocio
B3: 🔬 ¿QUÉ PASARÍA SI...?
B4: Probá una decisión sin tocar tus datos reales.
B6: =IF(NOT(Sim_DatosSuficientes),"Necesitás cargar ventas reales antes de simular escenarios. → Ir a 🛒 Ventas","")
B7: ESCENARIO ACTUAL
B8: Ventas | D8: =Sim_Base_Ventas
B9: Costos de venta | D9: =Sim_Base_CostosVenta
B10: Ganancia de productos | D10: =Sim_Base_GananciaProductos
B11: Gastos | D11: =Sim_Base_Gastos
B12: Ganancia real | D12: =Sim_Base_GananciaReal
B13: Margen | D13: =Sim_Base_Margen
B15: Escenario A | F15: Escenario B | J15: Escenario C
B16: Δ Precio % | D16: 0 | F16: Δ Precio % | H16: 0 | J16: Δ Precio % | L16: 0
B17: Δ Cantidad de ventas % | D17: 0 | F17: Δ Cantidad de ventas % | H17: 0 | J17: Δ Cantidad de ventas % | L17: 0
B18: Δ Margen (pp) | D18: 0 | F18: Δ Margen (pp) | H18: 0 | J18: Δ Margen (pp) | L18: 0
B19: Δ Gastos ($) | D19: 0 | F19: Δ Gastos ($) | H19: 0 | J19: Δ Gastos ($) | L19: 0
B20: Δ Publicidad ($) | D20: 0 | F20: Δ Publicidad ($) | H20: 0 | J20: Δ Publicidad ($) | L20: 0
B22: ESCENARIO PROYECTADO
B23: Ventas | D23: =Sim_A_VentasProyectadas | F23: Ventas | H23: =Sim_B_VentasProyectadas | J23: Ventas | L23: =Sim_C_VentasProyectadas
B24: Costos de venta | D24: =Sim_A_CostosVentaProyectados | F24: Costos de venta | H24: =Sim_B_CostosVentaProyectados | J24: Costos de venta | L24: =Sim_C_CostosVentaProyectados
B25: Ganancia de productos | D25: =Sim_A_GananciaProductosProyectada | F25: Ganancia de productos | H25: =Sim_B_GananciaProductosProyectada | J25: Ganancia de productos | L25: =Sim_C_GananciaProductosProyectada
B26: Gastos | D26: =Sim_A_GastosProyectados | F26: Gastos | H26: =Sim_B_GastosProyectados | J26: Gastos | L26: =Sim_C_GastosProyectados
B27: Ganancia real | D27: =Sim_A_GananciaRealProyectada | F27: Ganancia real | H27: =Sim_B_GananciaRealProyectada | J27: Ganancia real | L27: =Sim_C_GananciaRealProyectada
B28: Margen | D28: =Sim_A_MargenProyectado | F28: Margen | H28: =Sim_B_MargenProyectado | J28: Margen | L28: =Sim_C_MargenProyectado
B29: DIFERENCIA | F29: DIFERENCIA | J29: DIFERENCIA
B30: =Sim_A_Diferencia | F30: =Sim_B_Diferencia | J30: =Sim_C_Diferencia
B31: =IF(Sim_A_GastosAjustados=TRUE,"Ajustamos tus gastos proyectados a $0 porque el valor ingresado los volvía negativos.","") | F31: =IF(Sim_B_GastosAjustados=TRUE,"Ajustamos tus gastos proyectados a $0 porque el valor ingresado los volvía negativos.","") | J31: =IF(Sim_C_GastosAjustados=TRUE,"Ajustamos tus gastos proyectados a $0 porque el valor ingresado los volvía negativos.","")

Sheet 🎬 Demo
B1: 🏠 Inicio | D1: ⚙️ Configuración | F1: 📦 Productos | H1: 🛒 Ventas | J1: 💸 Gastos | L1: 🎯 Objetivos | N1: 🔬 Simulador | Q1: ="🎬 DEMO"
B3: 🎬 DEMO
B4: Así se ve Profitly con datos de ejemplo.
B6: Estás viendo datos de ejemplo. Cuando quieras, pasá a 🚀 Mi Negocio para cargar los tuyos.
B9: VENTAS | F9: GANANCIA REAL | J9: MARGEN | N9: GASTOS
B10: =DemoKPI_VentasPeriodo | F10: =DemoKPI_GananciaReal | J10: =DemoKPI_MargenReal | N10: =DemoKPI_GastosPeriodo
B13: TICKET PROMEDIO | F13: OBJETIVO MENSUAL | J13: PROGRESO
B14: =DemoKPI_TicketPromedio | F14: =DemoKPI_Objetivo | J14: =IFERROR(DemoKPI_ProgresoPct,0)
B17: 💡 Lo que Profitly encontró en tus números
B18: 🔥 Set de regalo premium genera la mayor parte de tu ganancia.
B19: 🎯 Te faltan $45.000 de ganancia para alcanzar tu objetivo.
R115: Alcanzado | S115: Restante
R116: =DemoKPI_GananciaReal | S116: =MAX(DemoKPI_Objetivo-DemoKPI_GananciaReal,0)

Sheet _Config
A1: Nombre | B1: Valor
A6: Cfg_PeriodoInicio | B6: =IF('🏠 Inicio'!$G$7="Mes pasado",EOMONTH(TODAY(),-2)+1,IF('🏠 Inicio'!$G$7="Últimos 3 meses",EOMONTH(TODAY(),-3)+1,EOMONTH(TODAY(),-1)+1))
A7: Cfg_PeriodoFin | B7: =IF('🏠 Inicio'!$G$7="Mes pasado",EOMONTH(TODAY(),-1),TODAY())
A8: Cfg_MargenAlertaUmbral | B8: 0.15
A10: Cfg_PeriodoInicio_Ant | B10: =EDATE(Cfg_PeriodoInicio,-1)
A11: Cfg_PeriodoFin_Ant | B11: =EDATE(Cfg_PeriodoInicio,0)-1

Sheet _Listas
A1: Lst_Categorias | B1: Lst_Canales | C1: Lst_CategoriasGasto | D1: Lst_TiposGasto | E1: Lst_Monedas | F1: Lst_PeriodosRapidos
A2: General | B2: Local | C2: Publicidad | D2: Fijo | E2: $ | F2: Este mes
A3: Alimentos | B3: Online | C3: Software/Suscripciones | D3: Variable | E3: US$ | F3: Mes pasado
A4: Indumentaria | B4: Mayorista | C4: Internet | D4: Único | E4: € | F4: Últimos 3 meses
A5: Accesorios | B5: Redes sociales | C5: Packaging general | E5: S/ | F5: Personalizado
A6: Hogar | B6: Feria | C6: Herramientas | E6: MX$
A7: Belleza | C7: Otros
A8: Servicios

Sheet _GastosCalc
A1: Métrica | B1: Valor
A2: Gastos del período | B2: =SUMIFS(tbl_Gastos[Importe],tbl_Gastos[Fecha],">="&Cfg_PeriodoInicio,tbl_Gastos[Fecha],"<="&Cfg_PeriodoFin)
A3: Gastos del período anterior | B3: =SUMIFS(tbl_Gastos[Importe],tbl_Gastos[Fecha],">="&Cfg_PeriodoInicio_Ant,tbl_Gastos[Fecha],"<="&Cfg_PeriodoFin_Ant)

Sheet _DashboardData
A1: Métrica | B1: Actual | C1: Anterior | E1: Alcanzado | F1: Restante
A2: Ventas del período | B2: =SUMIFS(tbl_Ventas[Venta total],tbl_Ventas[Fecha],">="&Cfg_PeriodoInicio,tbl_Ventas[Fecha],"<="&Cfg_PeriodoFin) | C2: =SUMIFS(tbl_Ventas[Venta total],tbl_Ventas[Fecha],">="&Cfg_PeriodoInicio_Ant,tbl_Ventas[Fecha],"<="&Cfg_PeriodoFin_Ant) | E2: =MIN(Obj_GananciaActual,Obj_GananciaObjetivo) | F2: =Obj_Restante
A3: Costos de venta del período | B3: =SUMIFS(tbl_Ventas[Costo total de la venta],tbl_Ventas[Fecha],">="&Cfg_PeriodoInicio,tbl_Ventas[Fecha],"<="&Cfg_PeriodoFin) | C3: =SUMIFS(tbl_Ventas[Costo total de la venta],tbl_Ventas[Fecha],">="&Cfg_PeriodoInicio_Ant,tbl_Ventas[Fecha],"<="&Cfg_PeriodoFin_Ant)
A4: Ganancia de productos | B4: =KPI_VentasPeriodo-KPI_CostosVentaPeriodo | C4: =KPI_VentasPeriodo_Ant-KPI_CostosVentaPeriodo_Ant
A5: Gastos del período | B5: =GastosCalc_PeriodoActual | C5: =GastosCalc_PeriodoAnterior
A6: Ganancia real | B6: =KPI_GananciaProductos-KPI_GastosPeriodo | C6: =KPI_GananciaProductos_Ant-KPI_GastosPeriodo_Ant
A7: Margen real | B7: =IF(KPI_VentasPeriodo=0,Txt_SinVentas,KPI_GananciaReal/KPI_VentasPeriodo) | C7: =IF(KPI_VentasPeriodo_Ant=0,Txt_SinVentas,KPI_GananciaReal_Ant/KPI_VentasPeriodo_Ant)
A8: Cantidad de ventas | B8: =COUNTIFS(tbl_Ventas[Fecha],">="&Cfg_PeriodoInicio,tbl_Ventas[Fecha],"<="&Cfg_PeriodoFin) | C8: =COUNTIFS(tbl_Ventas[Fecha],">="&Cfg_PeriodoInicio_Ant,tbl_Ventas[Fecha],"<="&Cfg_PeriodoFin_Ant)
A9: Ticket promedio | B9: =IF(KPI_CantidadVentas=0,Txt_SinVentas,KPI_VentasPeriodo/KPI_CantidadVentas) | C9: =IF(KPI_CantidadVentas_Ant=0,Txt_SinVentas,KPI_VentasPeriodo_Ant/KPI_CantidadVentas_Ant)
A12: Deltas vs. período anterior
A13: KPI_VentasPeriodo | B13: =IFERROR((KPI_VentasPeriodo-KPI_VentasPeriodo_Ant)/ABS(KPI_VentasPeriodo_Ant),"")
A14: KPI_GananciaReal | B14: =IFERROR((KPI_GananciaReal-KPI_GananciaReal_Ant)/ABS(KPI_GananciaReal_Ant),"")
A15: KPI_MargenReal | B15: =IFERROR((KPI_MargenReal-KPI_MargenReal_Ant)/ABS(KPI_MargenReal_Ant),"")
A16: KPI_GastosPeriodo | B16: =IFERROR((KPI_GastosPeriodo-KPI_GastosPeriodo_Ant)/ABS(KPI_GastosPeriodo_Ant),"")
A17: KPI_TicketPromedio | B17: =IFERROR((KPI_TicketPromedio-KPI_TicketPromedio_Ant)/ABS(KPI_TicketPromedio_Ant),"")
A20: Tendencia (últimos 6 períodos) | B20: =IF(COUNTA(tbl_Ventas[Fecha])=0,0,TODAY()-MIN(tbl_Ventas[Fecha]))
B21: =IF(Dash_DiasHistorial<60,"Semanal","Mensual")
A22: Periodo | B22: Ventas | C22: Ganancia
A23: =IF(Dash_Granularidad="Mensual",TEXT(EDATE(TODAY(),-5),"MMM"),"Sem. "&TEXT(TODAY()-5*7,"DD/MM")) | B23: =IF(Dash_Granularidad="Mensual",SUMIFS(tbl_Ventas[Venta total],tbl_Ventas[Fecha],">="&EOMONTH(TODAY(),-5-1)+1,tbl_Ventas[Fecha],"<="&EOMONTH(TODAY(),-5)),SUMIFS(tbl_Ventas[Venta total],tbl_Ventas[Fecha],">="&TODAY()-5*7-6,tbl_Ventas[Fecha],"<="&TODAY()-5*7)) | C23: =IF(Dash_Granularidad="Mensual",SUMIFS(tbl_Ventas[Ganancia],tbl_Ventas[Fecha],">="&EOMONTH(TODAY(),-5-1)+1,tbl_Ventas[Fecha],"<="&EOMONTH(TODAY(),-5)),SUMIFS(tbl_Ventas[Ganancia],tbl_Ventas[Fecha],">="&TODAY()-5*7-6,tbl_Ventas[Fecha],"<="&TODAY()-5*7))
A24: =IF(Dash_Granularidad="Mensual",TEXT(EDATE(TODAY(),-4),"MMM"),"Sem. "&TEXT(TODAY()-4*7,"DD/MM")) | B24: =IF(Dash_Granularidad="Mensual",SUMIFS(tbl_Ventas[Venta total],tbl_Ventas[Fecha],">="&EOMONTH(TODAY(),-4-1)+1,tbl_Ventas[Fecha],"<="&EOMONTH(TODAY(),-4)),SUMIFS(tbl_Ventas[Venta total],tbl_Ventas[Fecha],">="&TODAY()-4*7-6,tbl_Ventas[Fecha],"<="&TODAY()-4*7)) | C24: =IF(Dash_Granularidad="Mensual",SUMIFS(tbl_Ventas[Ganancia],tbl_Ventas[Fecha],">="&EOMONTH(TODAY(),-4-1)+1,tbl_Ventas[Fecha],"<="&EOMONTH(TODAY(),-4)),SUMIFS(tbl_Ventas[Ganancia],tbl_Ventas[Fecha],">="&TODAY()-4*7-6,tbl_Ventas[Fecha],"<="&TODAY()-4*7))
A25: =IF(Dash_Granularidad="Mensual",TEXT(EDATE(TODAY(),-3),"MMM"),"Sem. "&TEXT(TODAY()-3*7,"DD/MM")) | B25: =IF(Dash_Granularidad="Mensual",SUMIFS(tbl_Ventas[Venta total],tbl_Ventas[Fecha],">="&EOMONTH(TODAY(),-3-1)+1,tbl_Ventas[Fecha],"<="&EOMONTH(TODAY(),-3)),SUMIFS(tbl_Ventas[Venta total],tbl_Ventas[Fecha],">="&TODAY()-3*7-6,tbl_Ventas[Fecha],"<="&TODAY()-3*7)) | C25: =IF(Dash_Granularidad="Mensual",SUMIFS(tbl_Ventas[Ganancia],tbl_Ventas[Fecha],">="&EOMONTH(TODAY(),-3-1)+1,tbl_Ventas[Fecha],"<="&EOMONTH(TODAY(),-3)),SUMIFS(tbl_Ventas[Ganancia],tbl_Ventas[Fecha],">="&TODAY()-3*7-6,tbl_Ventas[Fecha],"<="&TODAY()-3*7))
A26: =IF(Dash_Granularidad="Mensual",TEXT(EDATE(TODAY(),-2),"MMM"),"Sem. "&TEXT(TODAY()-2*7,"DD/MM")) | B26: =IF(Dash_Granularidad="Mensual",SUMIFS(tbl_Ventas[Venta total],tbl_Ventas[Fecha],">="&EOMONTH(TODAY(),-2-1)+1,tbl_Ventas[Fecha],"<="&EOMONTH(TODAY(),-2)),SUMIFS(tbl_Ventas[Venta total],tbl_Ventas[Fecha],">="&TODAY()-2*7-6,tbl_Ventas[Fecha],"<="&TODAY()-2*7)) | C26: =IF(Dash_Granularidad="Mensual",SUMIFS(tbl_Ventas[Ganancia],tbl_Ventas[Fecha],">="&EOMONTH(TODAY(),-2-1)+1,tbl_Ventas[Fecha],"<="&EOMONTH(TODAY(),-2)),SUMIFS(tbl_Ventas[Ganancia],tbl_Ventas[Fecha],">="&TODAY()-2*7-6,tbl_Ventas[Fecha],"<="&TODAY()-2*7))
A27: =IF(Dash_Granularidad="Mensual",TEXT(EDATE(TODAY(),-1),"MMM"),"Sem. "&TEXT(TODAY()-1*7,"DD/MM")) | B27: =IF(Dash_Granularidad="Mensual",SUMIFS(tbl_Ventas[Venta total],tbl_Ventas[Fecha],">="&EOMONTH(TODAY(),-1-1)+1,tbl_Ventas[Fecha],"<="&EOMONTH(TODAY(),-1)),SUMIFS(tbl_Ventas[Venta total],tbl_Ventas[Fecha],">="&TODAY()-1*7-6,tbl_Ventas[Fecha],"<="&TODAY()-1*7)) | C27: =IF(Dash_Granularidad="Mensual",SUMIFS(tbl_Ventas[Ganancia],tbl_Ventas[Fecha],">="&EOMONTH(TODAY(),-1-1)+1,tbl_Ventas[Fecha],"<="&EOMONTH(TODAY(),-1)),SUMIFS(tbl_Ventas[Ganancia],tbl_Ventas[Fecha],">="&TODAY()-1*7-6,tbl_Ventas[Fecha],"<="&TODAY()-1*7))
A28: =IF(Dash_Granularidad="Mensual",TEXT(EDATE(TODAY(),-0),"MMM"),"Sem. "&TEXT(TODAY()-0*7,"DD/MM")) | B28: =IF(Dash_Granularidad="Mensual",SUMIFS(tbl_Ventas[Venta total],tbl_Ventas[Fecha],">="&EOMONTH(TODAY(),-0-1)+1,tbl_Ventas[Fecha],"<="&EOMONTH(TODAY(),-0)),SUMIFS(tbl_Ventas[Venta total],tbl_Ventas[Fecha],">="&TODAY()-0*7-6,tbl_Ventas[Fecha],"<="&TODAY()-0*7)) | C28: =IF(Dash_Granularidad="Mensual",SUMIFS(tbl_Ventas[Ganancia],tbl_Ventas[Fecha],">="&EOMONTH(TODAY(),-0-1)+1,tbl_Ventas[Fecha],"<="&EOMONTH(TODAY(),-0)),SUMIFS(tbl_Ventas[Ganancia],tbl_Ventas[Fecha],">="&TODAY()-0*7-6,tbl_Ventas[Fecha],"<="&TODAY()-0*7))
A31: Ganancia por producto (top 8)
A32: Producto | B32: Ganancia total
A33: =IFERROR(INDEX(tbl_Productos[Producto],MATCH(B33,tbl_Productos[Ganancia total],0)),"") | B33: =IFERROR(LARGE(tbl_Productos[Ganancia total],1),"")
A34: =IFERROR(INDEX(tbl_Productos[Producto],MATCH(B34,tbl_Productos[Ganancia total],0)),"") | B34: =IFERROR(LARGE(tbl_Productos[Ganancia total],2),"")
A35: =IFERROR(INDEX(tbl_Productos[Producto],MATCH(B35,tbl_Productos[Ganancia total],0)),"") | B35: =IFERROR(LARGE(tbl_Productos[Ganancia total],3),"")
A36: =IFERROR(INDEX(tbl_Productos[Producto],MATCH(B36,tbl_Productos[Ganancia total],0)),"") | B36: =IFERROR(LARGE(tbl_Productos[Ganancia total],4),"")
A37: =IFERROR(INDEX(tbl_Productos[Producto],MATCH(B37,tbl_Productos[Ganancia total],0)),"") | B37: =IFERROR(LARGE(tbl_Productos[Ganancia total],5),"")
A38: =IFERROR(INDEX(tbl_Productos[Producto],MATCH(B38,tbl_Productos[Ganancia total],0)),"") | B38: =IFERROR(LARGE(tbl_Productos[Ganancia total],6),"")
A39: =IFERROR(INDEX(tbl_Productos[Producto],MATCH(B39,tbl_Productos[Ganancia total],0)),"") | B39: =IFERROR(LARGE(tbl_Productos[Ganancia total],7),"")
A40: =IFERROR(INDEX(tbl_Productos[Producto],MATCH(B40,tbl_Productos[Ganancia total],0)),"") | B40: =IFERROR(LARGE(tbl_Productos[Ganancia total],8),"")
A41: Otros | B41: =MAX(SUM(tbl_Productos[Ganancia total])-SUM(B33:B40),0)

Sheet _Objetivos_Calc
A1: Métrica | B1: Valor
A2: Ganancia objetivo | B2: =IFERROR(INDEX(tbl_Objetivos[Objetivo de ganancia],MATCH(EOMONTH(TODAY(),-1)+1,tbl_Objetivos[Periodo (Mes-Año)],0)),Cfg_ObjetivoMensualDefault)
A3: Ganancia actual | B3: =KPI_GananciaReal
A4: Restante | B4: =MAX(Obj_GananciaObjetivo-Obj_GananciaActual,0)
A5: Progreso % | B5: =IF(Obj_GananciaObjetivo<=0,Txt_ObjetivoInvalido,MIN(Obj_GananciaActual/Obj_GananciaObjetivo,1))
A6: Días restantes | B6: =DAY(EOMONTH(TODAY(),0))-DAY(TODAY())
A7: Ganancia diaria necesaria | B7: =IF(Obj_DiasRestantes=0,Txt_UltimoDia,Obj_Restante/Obj_DiasRestantes)
A8: Facturación necesaria | B8: =IF(OR(NOT(ISNUMBER(KPI_MargenReal)),KPI_MargenReal<=0),Txt_ObjetivoInvalido,Obj_Restante/KPI_MargenReal)
A9: Ventas necesarias | B9: =IF(OR(NOT(ISNUMBER(KPI_TicketPromedio)),KPI_TicketPromedio<=0,NOT(ISNUMBER(Obj_FacturacionNecesaria))),Txt_FaltaHistorial,Obj_FacturacionNecesaria/KPI_TicketPromedio)
A19: Historial diario (90 días)
A20: Fecha | B20: Ganancia del día
A21: =TODAY()-89 | B21: =SUMIFS(tbl_Ventas[Ganancia],tbl_Ventas[Fecha],A21)
A22: =TODAY()-88 | B22: =SUMIFS(tbl_Ventas[Ganancia],tbl_Ventas[Fecha],A22)
A23: =TODAY()-87 | B23: =SUMIFS(tbl_Ventas[Ganancia],tbl_Ventas[Fecha],A23)
A24: =TODAY()-86 | B24: =SUMIFS(tbl_Ventas[Ganancia],tbl_Ventas[Fecha],A24)
A25: =TODAY()-85 | B25: =SUMIFS(tbl_Ventas[Ganancia],tbl_Ventas[Fecha],A25)
A26: =TODAY()-84 | B26: =SUMIFS(tbl_Ventas[Ganancia],tbl_Ventas[Fecha],A26)
A27: =TODAY()-83 | B27: =SUMIFS(tbl_Ventas[Ganancia],tbl_Ventas[Fecha],A27)
A28: =TODAY()-82 | B28: =SUMIFS(tbl_Ventas[Ganancia],tbl_Ventas[Fecha],A28)
A29: =TODAY()-81 | B29: =SUMIFS(tbl_Ventas[Ganancia],tbl_Ventas[Fecha],A29)
A30: =TODAY()-80 | B30: =SUMIFS(tbl_Ventas[Ganancia],tbl_Ventas[Fecha],A30)
A31: =TODAY()-79 | B31: =SUMIFS(tbl_Ventas[Ganancia],tbl_Ventas[Fecha],A31)
A32: =TODAY()-78 | B32: =SUMIFS(tbl_Ventas[Ganancia],tbl_Ventas[Fecha],A32)
A33: =TODAY()-77 | B33: =SUMIFS(tbl_Ventas[Ganancia],tbl_Ventas[Fecha],A33)
A34: =TODAY()-76 | B34: =SUMIFS(tbl_Ventas[Ganancia],tbl_Ventas[Fecha],A34)
A35: =TODAY()-75 | B35: =SUMIFS(tbl_Ventas[Ganancia],tbl_Ventas[Fecha],A35)
A36: =TODAY()-74 | B36: =SUMIFS(tbl_Ventas[Ganancia],tbl_Ventas[Fecha],A36)
A37: =TODAY()-73 | B37: =SUMIFS(tbl_Ventas[Ganancia],tbl_Ventas[Fecha],A37)
A38: =TODAY()-72 | B38: =SUMIFS(tbl_Ventas[Ganancia],tbl_Ventas[Fecha],A38)
A39: =TODAY()-71 | B39: =SUMIFS(tbl_Ventas[Ganancia],tbl_Ventas[Fecha],A39)
A40: =TODAY()-70 | B40: =SUMIFS(tbl_Ventas[Ganancia],tbl_Ventas[Fecha],A40)
A41: =TODAY()-69 | B41: =SUMIFS(tbl_Ventas[Ganancia],tbl_Ventas[Fecha],A41)
A42: =TODAY()-68 | B42: =SUMIFS(tbl_Ventas[Ganancia],tbl_Ventas[Fecha],A42)
A43: =TODAY()-67 | B43: =SUMIFS(tbl_Ventas[Ganancia],tbl_Ventas[Fecha],A43)
A44: =TODAY()-66 | B44: =SUMIFS(tbl_Ventas[Ganancia],tbl_Ventas[Fecha],A44)
A45: =TODAY()-65 | B45: =SUMIFS(tbl_Ventas[Ganancia],tbl_Ventas[Fecha],A45)
A46: =TODAY()-64 | B46: =SUMIFS(tbl_Ventas[Ganancia],tbl_Ventas[Fecha],A46)
A47: =TODAY()-63 | B47: =SUMIFS(tbl_Ventas[Ganancia],tbl_Ventas[Fecha],A47)
A48: =TODAY()-62 | B48: =SUMIFS(tbl_Ventas[Ganancia],tbl_Ventas[Fecha],A48)
A49: =TODAY()-61 | B49: =SUMIFS(tbl_Ventas[Ganancia],tbl_Ventas[Fecha],A49)
...

Sheet _Insights_Rules
A1: RuleID | B1: Condición | C1: Plantilla | D1: Prioridad | E1: Activa
A2: R0 | B2: =COUNTA(tbl_Ventas[Fecha])<5 | C2: Agregá más datos para obtener insights. | D2: 0 | E2: TRUE
A3: R1 | B3: =IF(AND(ISNUMBER(KPI_MargenReal),ISNUMBER(KPI_MargenReal_Ant)),(KPI_MargenReal_Ant-KPI_MargenReal)>0.02,FALSE) | C3: ⚠️ Tu margen cayó {delta} este mes. | D3: 1 | E3: TRUE
A4: R2 | B4: =IF(SUM(tbl_Productos[Ganancia total])>0,MAX(tbl_Productos[Ganancia total])/SUM(tbl_Productos[Ganancia total])>0.5,FALSE) | C4: 🔥 {producto} genera la mayor parte de tu ganancia. | D4: 2 | E4: TRUE
A5: R3 | B5: =IF(AND(ISNUMBER(Ins_ValorVentasDelta),ISNUMBER(Ins_ValorGananciaDelta)),(Ins_ValorVentasDelta-Ins_ValorGananciaDelta)>0.1,FALSE) | C5: 📈 Tus ventas aumentaron {ventasDelta}, pero tu ganancia solo aumentó {gananciaDelta}. | D5: 2 | E5: TRUE
A6: R4 | B6: =AND(Obj_GananciaObjetivo>0,Obj_Restante>0) | C6: 🎯 Te faltan {restante} de ganancia para alcanzar tu objetivo. | D6: 3 | E6: TRUE

Sheet _Insights_Engine
A1: Token | B1: Valor
A2: {delta} | B2: =IFERROR(TEXT(ABS(KPI_MargenReal-KPI_MargenReal_Ant),"0,0%"),"")
A3: {producto} | B3: =IF(COUNTA(tbl_Productos[Producto])=0,"",INDEX(tbl_Productos[Producto],MATCH(MAX(tbl_Productos[Ganancia total]),tbl_Productos[Ganancia total],0)))
A4: ventasDelta (numérico) | B4: =IFERROR((KPI_VentasPeriodo-KPI_VentasPeriodo_Ant)/KPI_VentasPeriodo_Ant,"")
A5: {ventasDelta} | B5: =IFERROR(TEXT(Ins_ValorVentasDelta,"0,0%"),"")
A6: gananciaDelta (numérico) | B6: =IFERROR((KPI_GananciaReal-KPI_GananciaReal_Ant)/ABS(KPI_GananciaReal_Ant),"")
A7: {gananciaDelta} | B7: =IFERROR(TEXT(Ins_ValorGananciaDelta,"0,0%"),"")
A8: {restante} | B8: =Cfg_Moneda&TEXT(Obj_Restante,"#,##0")
A11: Ranking de reglas activas
A12: RuleID | B12: Clave de orden | C12: Texto resuelto
A13: ='_Insights_Rules'!A2 | B13: =IF(AND('_Insights_Rules'!E2=TRUE,'_Insights_Rules'!B2=TRUE),'_Insights_Rules'!D2*100+2,999999) | C13: =SUBSTITUTE(SUBSTITUTE(SUBSTITUTE(SUBSTITUTE(SUBSTITUTE('_Insights_Rules'!C2,"{delta}",Ins_Delta),"{producto}",Ins_Producto),"{ventasDelta}",Ins_VentasDelta),"{gananciaDelta}",Ins_GananciaDelta),"{restante}",Ins_Restante)
A14: ='_Insights_Rules'!A3 | B14: =IF(AND('_Insights_Rules'!E3=TRUE,'_Insights_Rules'!B3=TRUE),'_Insights_Rules'!D3*100+3,999999) | C14: =SUBSTITUTE(SUBSTITUTE(SUBSTITUTE(SUBSTITUTE(SUBSTITUTE('_Insights_Rules'!C3,"{delta}",Ins_Delta),"{producto}",Ins_Producto),"{ventasDelta}",Ins_VentasDelta),"{gananciaDelta}",Ins_GananciaDelta),"{restante}",Ins_Restante)
A15: ='_Insights_Rules'!A4 | B15: =IF(AND('_Insights_Rules'!E4=TRUE,'_Insights_Rules'!B4=TRUE),'_Insights_Rules'!D4*100+4,999999) | C15: =SUBSTITUTE(SUBSTITUTE(SUBSTITUTE(SUBSTITUTE(SUBSTITUTE('_Insights_Rules'!C4,"{delta}",Ins_Delta),"{producto}",Ins_Producto),"{ventasDelta}",Ins_VentasDelta),"{gananciaDelta}",Ins_GananciaDelta),"{restante}",Ins_Restante)
A16: ='_Insights_Rules'!A5 | B16: =IF(AND('_Insights_Rules'!E5=TRUE,'_Insights_Rules'!B5=TRUE),'_Insights_Rules'!D5*100+5,999999) | C16: =SUBSTITUTE(SUBSTITUTE(SUBSTITUTE(SUBSTITUTE(SUBSTITUTE('_Insights_Rules'!C5,"{delta}",Ins_Delta),"{producto}",Ins_Producto),"{ventasDelta}",Ins_VentasDelta),"{gananciaDelta}",Ins_GananciaDelta),"{restante}",Ins_Restante)
A17: ='_Insights_Rules'!A6 | B17: =IF(AND('_Insights_Rules'!E6=TRUE,'_Insights_Rules'!B6=TRUE),'_Insights_Rules'!D6*100+6,999999) | C17: =SUBSTITUTE(SUBSTITUTE(SUBSTITUTE(SUBSTITUTE(SUBSTITUTE('_Insights_Rules'!C6,"{delta}",Ins_Delta),"{producto}",Ins_Producto),"{ventasDelta}",Ins_VentasDelta),"{gananciaDelta}",Ins_GananciaDelta),"{restante}",Ins_Restante)
A18: R0 activa (fallback) | B18: ='_Insights_Rules'!B2
A19: Salida final (hasta 4)
A20: Ins_Texto1 | B20: =IF(Ins_R0Activa=TRUE,IF(1=1,C13,""),IF(SMALL($B$13:$B$17,1)=999999,"",INDEX($C$13:$C$17,MATCH(SMALL($B$13:$B$17,1),$B$13:$B$17,0))))
A21: Ins_Texto2 | B21: =IF(Ins_R0Activa=TRUE,IF(2=1,C13,""),IF(SMALL($B$13:$B$17,2)=999999,"",INDEX($C$13:$C$17,MATCH(SMALL($B$13:$B$17,2),$B$13:$B$17,0))))
A22: Ins_Texto3 | B22: =IF(Ins_R0Activa=TRUE,IF(3=1,C13,""),IF(SMALL($B$13:$B$17,3)=999999,"",INDEX($C$13:$C$17,MATCH(SMALL($B$13:$B$17,3),$B$13:$B$17,0))))
A23: Ins_Texto4 | B23: =IF(Ins_R0Activa=TRUE,IF(4=1,C13,""),IF(SMALL($B$13:$B$17,4)=999999,"",INDEX($C$13:$C$17,MATCH(SMALL($B$13:$B$17,4),$B$13:$B$17,0))))

Sheet _Simulador_Engine
A1: Métrica | B1: Valor
A2: Datos suficientes | B2: =KPI_CantidadVentas>=1
A4: Ventas | B4: =KPI_VentasPeriodo
A5: Costos de venta | B5: =KPI_CostosVentaPeriodo
A6: Ganancia de productos | B6: =KPI_GananciaProductos
A7: Gastos | B7: =KPI_GastosPeriodo
A8: Ganancia real | B8: =KPI_GananciaReal
A9: Margen | B9: =KPI_MargenReal
A10: Cantidad de ventas | B10: =KPI_CantidadVentas
A13: Escenario A
A14: Ventas proyectadas | B14: =IF(NOT(Sim_DatosSuficientes),Txt_FaltaHistorial,Sim_Base_Ventas*(1+Sim_A_DeltaVentas)*(1+Sim_A_DeltaPrecio))
A15: Costos de venta proyectados | B15: =IF(NOT(Sim_DatosSuficientes),Txt_FaltaHistorial,Sim_Base_CostosVenta*(1+Sim_A_DeltaVentas))
A16: Margen (por precio) | B16: =IF(NOT(Sim_DatosSuficientes),Txt_FaltaHistorial,IF(OR(NOT(ISNUMBER(Sim_A_VentasProyectadas)),Sim_A_VentasProyectadas<=0),0,(Sim_A_VentasProyectadas-Sim_A_CostosVentaProyectados)/Sim_A_VentasProyectadas))
A17: Margen proyectado (final) | B17: =IF(NOT(Sim_DatosSuficientes),Txt_FaltaHistorial,MIN(MAX(Sim_A_MargenPorPrecio+Sim_A_DeltaMargen,-2),0.95))
A18: Ganancia de productos proyectada | B18: =IF(NOT(Sim_DatosSuficientes),Txt_FaltaHistorial,Sim_A_VentasProyectadas*Sim_A_MargenProyectado)
A19: Gastos proyectados | B19: =IF(NOT(Sim_DatosSuficientes),Txt_FaltaHistorial,MAX(Sim_Base_Gastos+Sim_A_DeltaGastos+Sim_A_DeltaPublicidad,0))
A20: Gastos ajustados a 0 (flag) | B20: =IF(NOT(Sim_DatosSuficientes),FALSE,(Sim_Base_Gastos+Sim_A_DeltaGastos+Sim_A_DeltaPublicidad)<0)
A21: Ganancia real proyectada | B21: =IF(NOT(Sim_DatosSuficientes),Txt_FaltaHistorial,Sim_A_GananciaProductosProyectada-Sim_A_GastosProyectados)
A22: Diferencia | B22: =IF(NOT(Sim_DatosSuficientes),Txt_FaltaHistorial,Sim_A_GananciaRealProyectada-Sim_Base_GananciaReal)
A24: Escenario B
A25: Ventas proyectadas | B25: =IF(NOT(Sim_DatosSuficientes),Txt_FaltaHistorial,Sim_Base_Ventas*(1+Sim_B_DeltaVentas)*(1+Sim_B_DeltaPrecio))
A26: Costos de venta proyectados | B26: =IF(NOT(Sim_DatosSuficientes),Txt_FaltaHistorial,Sim_Base_CostosVenta*(1+Sim_B_DeltaVentas))
A27: Margen (por precio) | B27: =IF(NOT(Sim_DatosSuficientes),Txt_FaltaHistorial,IF(OR(NOT(ISNUMBER(Sim_B_VentasProyectadas)),Sim_B_VentasProyectadas<=0),0,(Sim_B_VentasProyectadas-Sim_B_CostosVentaProyectados)/Sim_B_VentasProyectadas))
A28: Margen proyectado (final) | B28: =IF(NOT(Sim_DatosSuficientes),Txt_FaltaHistorial,MIN(MAX(Sim_B_MargenPorPrecio+Sim_B_DeltaMargen,-2),0.95))
A29: Ganancia de productos proyectada | B29: =IF(NOT(Sim_DatosSuficientes),Txt_FaltaHistorial,Sim_B_VentasProyectadas*Sim_B_MargenProyectado)
A30: Gastos proyectados | B30: =IF(NOT(Sim_DatosSuficientes),Txt_FaltaHistorial,MAX(Sim_Base_Gastos+Sim_B_DeltaGastos+Sim_B_DeltaPublicidad,0))
A31: Gastos ajustados a 0 (flag) | B31: =IF(NOT(Sim_DatosSuficientes),FALSE,(Sim_Base_Gastos+Sim_B_DeltaGastos+Sim_B_DeltaPublicidad)<0)
A32: Ganancia real proyectada | B32: =IF(NOT(Sim_DatosSuficientes),Txt_FaltaHistorial,Sim_B_GananciaProductosProyectada-Sim_B_GastosProyectados)
A33: Diferencia | B33: =IF(NOT(Sim_DatosSuficientes),Txt_FaltaHistorial,Sim_B_GananciaRealProyectada-Sim_Base_GananciaReal)
A35: Escenario C
A36: Ventas proyectadas | B36: =IF(NOT(Sim_DatosSuficientes),Txt_FaltaHistorial,Sim_Base_Ventas*(1+Sim_C_DeltaVentas)*(1+Sim_C_DeltaPrecio))
A37: Costos de venta proyectados | B37: =IF(NOT(Sim_DatosSuficientes),Txt_FaltaHistorial,Sim_Base_CostosVenta*(1+Sim_C_DeltaVentas))
A38: Margen (por precio) | B38: =IF(NOT(Sim_DatosSuficientes),Txt_FaltaHistorial,IF(OR(NOT(ISNUMBER(Sim_C_VentasProyectadas)),Sim_C_VentasProyectadas<=0),0,(Sim_C_VentasProyectadas-Sim_C_CostosVentaProyectados)/Sim_C_VentasProyectadas))
A39: Margen proyectado (final) | B39: =IF(NOT(Sim_DatosSuficientes),Txt_FaltaHistorial,MIN(MAX(Sim_C_MargenPorPrecio+Sim_C_DeltaMargen,-2),0.95))
A40: Ganancia de productos proyectada | B40: =IF(NOT(Sim_DatosSuficientes),Txt_FaltaHistorial,Sim_C_VentasProyectadas*Sim_C_MargenProyectado)
A41: Gastos proyectados | B41: =IF(NOT(Sim_DatosSuficientes),Txt_FaltaHistorial,MAX(Sim_Base_Gastos+Sim_C_DeltaGastos+Sim_C_DeltaPublicidad,0))
A42: Gastos ajustados a 0 (flag) | B42: =IF(NOT(Sim_DatosSuficientes),FALSE,(Sim_Base_Gastos+Sim_C_DeltaGastos+Sim_C_DeltaPublicidad)<0)
A43: Ganancia real proyectada | B43: =IF(NOT(Sim_DatosSuficientes),Txt_FaltaHistorial,Sim_C_GananciaProductosProyectada-Sim_C_GastosProyectados)
A44: Diferencia | B44: =IF(NOT(Sim_DatosSuficientes),Txt_FaltaHistorial,Sim_C_GananciaRealProyectada-Sim_Base_GananciaReal)

Sheet _Demo_Datos
A1: Demo · Productos
B2: Producto | C2: Categoría | D2: Precio de venta | E2: Costo del producto | F2: Comisión % | G2: Packaging | H2: Envío / costo asociado | I2: Publicidad atribuida | J2: Otros costos | K2: Costo real de venta | L2: Ganancia por unidad | M2: Margen | N2: Unidades vendidas | O2: Ganancia total | Q2: Demo · Gastos | W2: Demo · Objetivos
B3: Vela aromática grande | C3: Hogar | D3: 4500 | E3: 1200 | F3: 0.08 | G3: 150 | H3: 0 | I3: 200 | J3: 50 | K3: =E3+(D3*F3)+G3+H3+I3+J3 | L3: =D3-K3 | M3: =IF(D3=0,"",L3/D3) | N3: =SUMIFS($D$22:$D$132,$C$22:$C$132,B3) | O3: =SUMIFS($L$22:$L$132,$C$22:$C$132,B3) | Q3: Fecha | R3: Categoría | S3: Descripción | T3: Importe | U3: Tipo de gasto | W3: Periodo | X3: Objetivo de ganancia
B4: Vela aromática chica | C4: Hogar | D4: 2200 | E4: 600 | F4: 0.08 | G4: 100 | H4: 0 | I4: 100 | J4: 30 | K4: =E4+(D4*F4)+G4+H4+I4+J4 | L4: =D4-K4 | M4: =IF(D4=0,"",L4/D4) | N4: =SUMIFS($D$22:$D$132,$C$22:$C$132,B4) | O4: =SUMIFS($L$22:$L$132,$C$22:$C$132,B4) | Q4: 46270 | R4: Software/Suscripciones | S4: Suscripción plataforma de ventas | T4: 8500 | U4: Fijo | W4: 46266 | X4: 600000
B5: Jabón artesanal | C5: Belleza | D5: 1800 | E5: 450 | F5: 0.05 | G5: 80 | H5: 0 | I5: 150 | J5: 20 | K5: =E5+(D5*F5)+G5+H5+I5+J5 | L5: =D5-K5 | M5: =IF(D5=0,"",L5/D5) | N5: =SUMIFS($D$22:$D$132,$C$22:$C$132,B5) | O5: =SUMIFS($L$22:$L$132,$C$22:$C$132,B5) | Q5: 46272 | R5: Internet | S5: Internet del local | T5: 6200 | U5: Fijo
B6: Set de regalo premium | C6: Hogar | D6: 9500 | E6: 3200 | F6: 0.1 | G6: 300 | H6: 500 | I6: 400 | J6: 100 | K6: =E6+(D6*F6)+G6+H6+I6+J6 | L6: =D6-K6 | M6: =IF(D6=0,"",L6/D6) | N6: =SUMIFS($D$22:$D$132,$C$22:$C$132,B6) | O6: =SUMIFS($L$22:$L$132,$C$22:$C$132,B6) | Q6: 46280 | R6: Publicidad | S6: Campaña redes sociales | T6: 15000 | U6: Variable
B7: Difusor de aromas | C7: Hogar | D7: 6800 | E7: 2900 | F7: 0.08 | G7: 200 | H7: 0 | I7: 300 | J7: 80 | K7: =E7+(D7*F7)+G7+H7+I7+J7 | L7: =D7-K7 | M7: =IF(D7=0,"",L7/D7) | N7: =SUMIFS($D$22:$D$132,$C$22:$C$132,B7) | O7: =SUMIFS($L$22:$L$132,$C$22:$C$132,B7) | Q7: 46240 | R7: Software/Suscripciones | S7: Suscripción plataforma de ventas | T7: 8500 | U7: Fijo
B8: Crema corporal | C8: Belleza | D8: 3200 | E8: 1400 | F8: 0.05 | G8: 120 | H8: 0 | I8: 200 | J8: 60 | K8: =E8+(D8*F8)+G8+H8+I8+J8 | L8: =D8-K8 | M8: =IF(D8=0,"",L8/D8) | N8: =SUMIFS($D$22:$D$132,$C$22:$C$132,B8) | O8: =SUMIFS($L$22:$L$132,$C$22:$C$132,B8) | Q8: 46242 | R8: Internet | S8: Internet del local | T8: 6200 | U8: Fijo
B9: Sahumerio x12 | C9: Hogar | D9: 1500 | E9: 700 | F9: 0.05 | G9: 60 | H9: 0 | I9: 50 | J9: 20 | K9: =E9+(D9*F9)+G9+H9+I9+J9 | L9: =D9-K9 | M9: =IF(D9=0,"",L9/D9) | N9: =SUMIFS($D$22:$D$132,$C$22:$C$132,B9) | O9: =SUMIFS($L$22:$L$132,$C$22:$C$132,B9) | Q9: 46250 | R9: Publicidad | S9: Campaña redes sociales | T9: 15000 | U9: Variable
B10: Kit spa en casa | C10: Belleza | D10: 12000 | E10: 6500 | F10: 0.1 | G10: 350 | H10: 800 | I10: 500 | J10: 150 | K10: =E10+(D10*F10)+G10+H10+I10+J10 | L10: =D10-K10 | M10: =IF(D10=0,"",L10/D10) | N10: =SUMIFS($D$22:$D$132,$C$22:$C$132,B10) | O10: =SUMIFS($L$22:$L$132,$C$22:$C$132,B10) | Q10: 46210 | R10: Software/Suscripciones | S10: Suscripción plataforma de ventas | T10: 8500 | U10: Fijo
Q11: 46212 | R11: Internet | S11: Internet del local | T11: 6200 | U11: Fijo
Q12: 46220 | R12: Publicidad | S12: Campaña redes sociales | T12: 15000 | U12: Variable
Q13: 46256 | R13: Herramientas | S13: Balanza nueva | T13: 22000 | U13: Único
Q14: 46271 | R14: Packaging general | S14: Cajas y etiquetas | T14: 9800 | U14: Variable
A20: Demo · Ventas
B21: Fecha | C21: Producto | D21: Cantidad | E21: Precio de venta | F21: Canal | G21: Comisión % | H21: Descuento | I21: Otros costos | J21: Venta total | K21: Costo total de la venta | L21: Ganancia
B22: 46187 | C22: Sahumerio x12 | D22: 2 | E22: =IFERROR(INDEX($D$3:$D$10,MATCH(C22,$B$3:$B$10,0)),0) | F22: Local | G22: =IFERROR(INDEX($F$3:$F$10,MATCH(C22,$B$3:$B$10,0)),0) | H22: 0 | I22: 0 | J22: =(D22*E22)-H22 | K22: =IFERROR(INDEX($K$3:$K$10,MATCH(C22,$B$3:$B$10,0))*D22,0) | L22: =J22-K22-I22
B23: 46187 | C23: Difusor de aromas | D23: 1 | E23: =IFERROR(INDEX($D$3:$D$10,MATCH(C23,$B$3:$B$10,0)),0) | F23: Mayorista | G23: =IFERROR(INDEX($F$3:$F$10,MATCH(C23,$B$3:$B$10,0)),0) | H23: 200 | I23: 0 | J23: =(D23*E23)-H23 | K23: =IFERROR(INDEX($K$3:$K$10,MATCH(C23,$B$3:$B$10,0))*D23,0) | L23: =J23-K23-I23
B24: 46189 | C24: Vela aromática grande | D24: 2 | E24: =IFERROR(INDEX($D$3:$D$10,MATCH(C24,$B$3:$B$10,0)),0) | F24: Redes sociales | G24: =IFERROR(INDEX($F$3:$F$10,MATCH(C24,$B$3:$B$10,0)),0) | H24: 0 | I24: 0 | J24: =(D24*E24)-H24 | K24: =IFERROR(INDEX($K$3:$K$10,MATCH(C24,$B$3:$B$10,0))*D24,0) | L24: =J24-K24-I24
B25: 46190 | C25: Vela aromática grande | D25: 2 | E25: =IFERROR(INDEX($D$3:$D$10,MATCH(C25,$B$3:$B$10,0)),0) | F25: Local | G25: =IFERROR(INDEX($F$3:$F$10,MATCH(C25,$B$3:$B$10,0)),0) | H25: 200 | I25: 0 | J25: =(D25*E25)-H25 | K25: =IFERROR(INDEX($K$3:$K$10,MATCH(C25,$B$3:$B$10,0))*D25,0) | L25: =J25-K25-I25
B26: 46192 | C26: Jabón artesanal | D26: 2 | E26: =IFERROR(INDEX($D$3:$D$10,MATCH(C26,$B$3:$B$10,0)),0) | F26: Local | G26: =IFERROR(INDEX($F$3:$F$10,MATCH(C26,$B$3:$B$10,0)),0) | H26: 200 | I26: 0 | J26: =(D26*E26)-H26 | K26: =IFERROR(INDEX($K$3:$K$10,MATCH(C26,$B$3:$B$10,0))*D26,0) | L26: =J26-K26-I26
B27: 46193 | C27: Vela aromática grande | D27: 1 | E27: =IFERROR(INDEX($D$3:$D$10,MATCH(C27,$B$3:$B$10,0)),0) | F27: Local | G27: =IFERROR(INDEX($F$3:$F$10,MATCH(C27,$B$3:$B$10,0)),0) | H27: 200 | I27: 0 | J27: =(D27*E27)-H27 | K27: =IFERROR(INDEX($K$3:$K$10,MATCH(C27,$B$3:$B$10,0))*D27,0) | L27: =J27-K27-I27
B28: 46193 | C28: Crema corporal | D28: 1 | E28: =IFERROR(INDEX($D$3:$D$10,MATCH(C28,$B$3:$B$10,0)),0) | F28: Redes sociales | G28: =IFERROR(INDEX($F$3:$F$10,MATCH(C28,$B$3:$B$10,0)),0) | H28: 0 | I28: 0 | J28: =(D28*E28)-H28 | K28: =IFERROR(INDEX($K$3:$K$10,MATCH(C28,$B$3:$B$10,0))*D28,0) | L28: =J28-K28-I28
B29: 46195 | C29: Jabón artesanal | D29: 3 | E29: =IFERROR(INDEX($D$3:$D$10,MATCH(C29,$B$3:$B$10,0)),0) | F29: Online | G29: =IFERROR(INDEX($F$3:$F$10,MATCH(C29,$B$3:$B$10,0)),0) | H29: 0 | I29: 0 | J29: =(D29*E29)-H29 | K29: =IFERROR(INDEX($K$3:$K$10,MATCH(C29,$B$3:$B$10,0))*D29,0) | L29: =J29-K29-I29
B30: 46196 | C30: Vela aromática chica | D30: 2 | E30: =IFERROR(INDEX($D$3:$D$10,MATCH(C30,$B$3:$B$10,0)),0) | F30: Local | G30: =IFERROR(INDEX($F$3:$F$10,MATCH(C30,$B$3:$B$10,0)),0) | H30: 200 | I30: 0 | J30: =(D30*E30)-H30 | K30: =IFERROR(INDEX($K$3:$K$10,MATCH(C30,$B$3:$B$10,0))*D30,0) | L30: =J30-K30-I30
B31: 46198 | C31: Vela aromática chica | D31: 2 | E31: =IFERROR(INDEX($D$3:$D$10,MATCH(C31,$B$3:$B$10,0)),0) | F31: Redes sociales | G31: =IFERROR(INDEX($F$3:$F$10,MATCH(C31,$B$3:$B$10,0)),0) | H31: 0 | I31: 0 | J31: =(D31*E31)-H31 | K31: =IFERROR(INDEX($K$3:$K$10,MATCH(C31,$B$3:$B$10,0))*D31,0) | L31: =J31-K31-I31
B32: 46199 | C32: Jabón artesanal | D32: 2 | E32: =IFERROR(INDEX($D$3:$D$10,MATCH(C32,$B$3:$B$10,0)),0) | F32: Mayorista | G32: =IFERROR(INDEX($F$3:$F$10,MATCH(C32,$B$3:$B$10,0)),0) | H32: 0 | I32: 0 | J32: =(D32*E32)-H32 | K32: =IFERROR(INDEX($K$3:$K$10,MATCH(C32,$B$3:$B$10,0))*D32,0) | L32: =J32-K32-I32
B33: 46199 | C33: Vela aromática grande | D33: 1 | E33: =IFERROR(INDEX($D$3:$D$10,MATCH(C33,$B$3:$B$10,0)),0) | F33: Online | G33: =IFERROR(INDEX($F$3:$F$10,MATCH(C33,$B$3:$B$10,0)),0) | H33: 0 | I33: 0 | J33: =(D33*E33)-H33 | K33: =IFERROR(INDEX($K$3:$K$10,MATCH(C33,$B$3:$B$10,0))*D33,0) | L33: =J33-K33-I33
... B114: 46261 | C114: Jabón artesanal | D114: 1 | E114: =IFERROR(INDEX($D$3:$D$10,MATCH(C114,$B$3:$B$10,0)),0) | F114: Feria | G114: =IFERROR(INDEX($F$3:$F$10,MATCH(C114,$B$3:$B$10,0)),0) | H114: 500 | I114: 0 | J114: =(D114*E114)-H114 | K114: =IFERROR(INDEX($K$3:$K$10,MATCH(C114,$B$3:$B$10,0))*D114,0) | L114: =J114-K114-I114
A115: Demo · Ganancia por producto (top 8) | B115: 46261 | C115: Vela aromática grande | D115: 1 | E115: =IFERROR(INDEX($D$3:$D$10,MATCH(C115,$B$3:$B$10,0)),0) | F115: Online | G115: =IFERROR(INDEX($F$3:$F$10,MATCH(C115,$B$3:$B$10,0)),0) | H115: 0 | I115: 0 | J115: =(D115*E115)-H115 | K115: =IFERROR(INDEX($K$3:$K$10,MATCH(C115,$B$3:$B$10,0))*D115,0) | L115: =J115-K115-I115
A116: =IFERROR(INDEX($B$3:$B$10,MATCH(B116,$O$3:$O$10,0)),"") | B116: =IFERROR(LARGE($O$3:$O$10,1),"") | C116: Vela aromática grande | D116: 1 | E116: =IFERROR(INDEX($D$3:$D$10,MATCH(C116,$B$3:$B$10,0)),0) | F116: Mayorista | G116: =IFERROR(INDEX($F$3:$F$10,MATCH(C116,$B$3:$B$10,0)),0) | H116: 200 | I116: 0 | J116: =(D116*E116)-H116 | K116: =IFERROR(INDEX($K$3:$K$10,MATCH(C116,$B$3:$B$10,0))*D116,0) | L116: =J116-K116-I116
A117: =IFERROR(INDEX($B$3:$B$10,MATCH(B117,$O$3:$O$10,0)),"") | B117: =IFERROR(LARGE($O$3:$O$10,2),"") | C117: Vela aromática grande | D117: 2 | E117: =IFERROR(INDEX($D$3:$D$10,MATCH(C117,$B$3:$B$10,0)),0) | F117: Online | G117: =IFERROR(INDEX($F$3:$F$10,MATCH(C117,$B$3:$B$10,0)),0) | H117: 0 | I117: 0 | J117: =(D117*E117)-H117 | K117: =IFERROR(INDEX($K$3:$K$10,MATCH(C117,$B$3:$B$10,0))*D117,0) | L117: =J117-K117-I117
A118: =IFERROR(INDEX($B$3:$B$10,MATCH(B118,$O$3:$O$10,0)),"") | B118: =IFERROR(LARGE($O$3:$O$10,3),"") | C118: Difusor de aromas | D118: 1 | E118: =IFERROR(INDEX($D$3:$D$10,MATCH(C118,$B$3:$B$10,0)),0) | F118: Local | G118: =IFERROR(INDEX($F$3:$F$10,MATCH(C118,$B$3:$B$10,0)),0) | H118: 0 | I118: 0 | J118: =(D118*E118)-H118 | K118: =IFERROR(INDEX($K$3:$K$10,MATCH(C118,$B$3:$B$10,0))*D118,0) | L118: =J118-K118-I118
A119: =IFERROR(INDEX($B$3:$B$10,MATCH(B119,$O$3:$O$10,0)),"") | B119: =IFERROR(LARGE($O$3:$O$10,4),"") | C119: Vela aromática grande | D119: 2 | E119: =IFERROR(INDEX($D$3:$D$10,MATCH(C119,$B$3:$B$10,0)),0) | F119: Feria | G119: =IFERROR(INDEX($F$3:$F$10,MATCH(C119,$B$3:$B$10,0)),0) | H119: 0 | I119: 0 | J119: =(D119*E119)-H119 | K119: =IFERROR(INDEX($K$3:$K$10,MATCH(C119,$B$3:$B$10,0))*D119,0) | L119: =J119-K119-I119
A120: =IFERROR(INDEX($B$3:$B$10,MATCH(B120,$O$3:$O$10,0)),"") | B120: =IFERROR(LARGE($O$3:$O$10,5),"") | C120: Vela aromática grande | D120: 2 | E120: =IFERROR(INDEX($D$3:$D$10,MATCH(C120,$B$3:$B$10,0)),0) | F120: Local | G120: =IFERROR(INDEX($F$3:$F$10,MATCH(C120,$B$3:$B$10,0)),0) | H120: 500 | I120: 0 | J120: =(D120*E120)-H120 | K120: =IFERROR(INDEX($K$3:$K$10,MATCH(C120,$B$3:$B$10,0))*D120,0) | L120: =J120-K120-I120
A121: =IFERROR(INDEX($B$3:$B$10,MATCH(B121,$O$3:$O$10,0)),"") | B121: =IFERROR(LARGE($O$3:$O$10,6),"") | C121: Difusor de aromas | D121: 2 | E121: =IFERROR(INDEX($D$3:$D$10,MATCH(C121,$B$3:$B$10,0)),0) | F121: Redes sociales | G121: =IFERROR(INDEX($F$3:$F$10,MATCH(C121,$B$3:$B$10,0)),0) | H121: 200 | I121: 0 | J121: =(D121*E121)-H121 | K121: =IFERROR(INDEX($K$3:$K$10,MATCH(C121,$B$3:$B$10,0))*D121,0) | L121: =J121-K121-I121
A122: =IFERROR(INDEX($B$3:$B$10,MATCH(B122,$O$3:$O$10,0)),"") | B122: =IFERROR(LARGE($O$3:$O$10,7),"") | C122: Difusor de aromas | D122: 2 | E122: =IFERROR(INDEX($D$3:$D$10,MATCH(C122,$B$3:$B$10,0)),0) | F122: Feria | G122: =IFERROR(INDEX($F$3:$F$10,MATCH(C122,$B$3:$B$10,0)),0) | H122: 0 | I122: 0 | J122: =(D122*E122)-H122 | K122: =IFERROR(INDEX($K$3:$K$10,MATCH(C122,$B$3:$B$10,0))*D122,0) | L122: =J122-K122-I122
A123: =IFERROR(INDEX($B$3:$B$10,MATCH(B123,$O$3:$O$10,0)),"") | B123: =IFERROR(LARGE($O$3:$O$10,8),"") | C123: Kit spa en casa | D123: 1 | E123: =IFERROR(INDEX($D$3:$D$10,MATCH(C123,$B$3:$B$10,0)),0) | F123: Online | G123: =IFERROR(INDEX($F$3:$F$10,MATCH(C123,$B$3:$B$10,0)),0) | H123: 500 | I123: 0 | J123: =(D123*E123)-H123 | K123: =IFERROR(INDEX($K$3:$K$10,MATCH(C123,$B$3:$B$10,0))*D123,0) | L123: =J123-K123-I123
B124: 46268 | C124: Vela aromática chica | D124: 1 | E124: =IFERROR(INDEX($D$3:$D$10,MATCH(C124,$B$3:$B$10,0)),0) | F124: Local | G124: =IFERROR(INDEX($F$3:$F$10,MATCH(C124,$B$3:$B$10,0)),0) | H124: 0 | I124: 0 | J124: =(D124*E124)-H124 | K124: =IFERROR(INDEX($K$3:$K$10,MATCH(C124,$B$3:$B$10,0))*D124,0) | L124: =J124-K124-I124
B125: 46271 | C125: Vela aromática chica | D125: 1 | E125: =IFERROR(INDEX($D$3:$D$10,MATCH(C125,$B$3:$B$10,0)),0) | F125: Local | G125: =IFERROR(INDEX($F$3:$F$10,MATCH(C125,$B$3:$B$10,0)),0) | H125: 500 | I125: 0 | J125: =(D125*E125)-H125 | K125: =IFERROR(INDEX($K$3:$K$10,MATCH(C125,$B$3:$B$10,0))*D125,0) | L125: =J125-K125-I125
...

Sheet _Textos
A1: Nombre | B1: Texto
A2: Txt_SinDatos | B2: No hay suficientes datos para calcular este indicador.
A3: Txt_SinVentas | B3: Todavía no cargaste ventas en este período.
A4: Txt_SinProductos | B4: Agregá tu primer producto para empezar.
A5: Txt_ProductoNoEncontrado | B5: Este producto ya no está en tu catálogo.
A6: Txt_ObjetivoInvalido | B6: Definí un objetivo mayor a tu ganancia actual.
A7: Txt_ObjetivoAlcanzado | B7: ¡Ya alcanzaste tu objetivo! 🎉
A8: Txt_FaltaHistorial | B8: Necesitás más historial de ventas para calcular esto con precisión.
A9: Txt_NombreDuplicado | B9: Ya existe un producto con este nombre. Elegí un nombre distinto para diferenciarlo.
A10: Txt_SinAlertas | B10: Ninguno de tus productos tiene el margen bajo. ¡Buen trabajo!
A11: Txt_UltimoDia | B11: Hoy es el último día del período — no queda tiempo para repartir lo que falta.
